Workbook

Sheet Istruzioni
B1: TEST DELL'ENNEAGRAMMA — Versione revisionata a 162 domande
B3: Origine di questo questionario
B4: Le 162 domande (18 per ciascuno dei 9 tipi) sono organizzate in 6 faccette omogenee per ogni tipo: Motivazione, Paura, Strategia, Relazioni, Pressione e Approfondimento. Le tre domande di Approfondimento sostituiscono le precedenti domande sulle «Frecce» e sono state formulate per aumentare la capacità di distinguere il tipo e offrire spunti utili al colloquio.
B6: Scopo
B7: Individuare il tipo di personalità prevalente secondo l'Enneagramma (tipi 1-9) e offrire una base strutturata per discutere il risultato con la persona che compila il questionario.
B9: Come si svolge
B10: 1. Compila il foglio «Test»: per ciascuna delle 162 domande scegli SI o NO dal menu a tendina, in base a come ti comporti abitualmente (non come vorresti essere).
B11: 2. Non ci sono risposte giuste o sbagliate: rispondi con la prima impressione. Concludi in una o due sedute.
B12: 3. I punteggi si calcolano automaticamente nel foglio «Punteggi» man mano che inserisci le risposte.
B14: Le 6 faccette
B15: • Motivazione — il desiderio di fondo che orienta le scelte del tipo.
B16: • Paura — la paura o preoccupazione centrale che il tipo cerca di evitare.
... B28: Questo è uno strumento di auto-conoscenza per facilitare una conversazione, non un test clinico né diagnostico. I risultati dipendono dall'onestà delle risposte e vanno trattati come ipotesi di lavoro da approfondire nel colloquio, non come un'etichetta definitiva.

Sheet Table 1
A1: ESITO NUMERO | B1: ESITO TESTO | C1: DOMANDA | D1: Faccetta | E1: Risposta (SI/NO)
A2: 3 | B2: Tipo 3 – Il Realizzatore | C2: Mi accorgo che a volte valuto me stesso in base a quanto sto producendo. | D2: Pressione
A3: 1 | B3: Tipo 1 – Il Riformatore | C3: Temo che un errore importante possa dire qualcosa di negativo sul mio valore come persona. | D3: Paura
A4: 6 | B4: Tipo 6 – Il Leale | C4: Mi rassicura sapere in anticipo che cosa ci si aspetta da me e che cosa posso aspettarmi dagli altri. | D4: Motivazione
A5: 6 | B5: Tipo 6 – Il Leale | C5: Apprezzo gli ambienti in cui so a chi posso rivolgermi in caso di difficoltà. | D5: Strategia
A6: 5 | B6: Tipo 5 – L'Osservatore | C6: Mi trovo meglio nelle conversazioni che hanno un contenuto sostanziale rispetto alle chiacchiere generiche. | D6: Strategia
A7: 7 | B7: Tipo 7 – L'Entusiasta | C7: A volte temo di rimanere bloccato in una situazione dolorosa senza una via d’uscita. | D7: Paura
A8: 4 | B8: Tipo 4 – L'Individualista | C8: Il confronto con ciò che gli altri vivono può farmi percepire più chiaramente cosa sento mancare nella mia esperienza. | D8: Strategia
A9: 2 | B9: Tipo 2 – L'Altruista | C9: Posso accorgermi che il mio modo di aiutare risponde al bisogno di sentirmi indispensabile più che al bisogno dell’altro. | D9: Approfondimento
A10: 2 | B10: Tipo 2 – L'Altruista | C10: Mi capita di dare consigli o aiuto anche quando non mi è stato esplicitamente richiesto. | D10: Strategia
A11: 9 | B11: Tipo 9 – Il Pacificatore | C11: Posso rimandare una decisione perché non sento ancora chiaramente quale sia la mia priorità. | D11: Paura
A12: 8 | B12: Tipo 8 – Il Protettore | C12: Mi irrita particolarmente sentirmi limitato da qualcuno che non considero autorevole o corretto. | D12: Paura
A13: 5 | B13: Tipo 5 – L'Osservatore | C13: Posso accumulare informazioni molto oltre il necessario prima di sentirmi pronto ad agire. | D13: Strategia
... A163: 2 | B163: Tipo 2 – L'Altruista | C163: Nelle relazioni più strette, tendo a mettere i bisogni dell’altro prima dei miei, anche senza che me lo chieda esplicitamente. | D163: Relazioni

Sheet Punteggi
A1: PUNTEGGI AUTOMATICI
A3: Tipo | B3: Nome | C3: Motivazione | D3: Paura | E3: Strategia | F3: Relazioni | G3: Pressione | H3: Approfondimento | I3: Totale (max 18) | J3: %
A4: Tipo 1 | B4: Il Riformatore | C4: =COUNTIFS('Table 1'!$B$2:$B$163,"Tipo 1*",'Table 1'!$D$2:$D$163,"Motivazione",'Table 1'!$E$2:$E$163,"SI") -> 0 | D4: =COUNTIFS('Table 1'!$B$2:$B$163,"Tipo 1*",'Table 1'!$D$2:$D$163,"Paura",'Table 1'!$E$2:$E$163,"SI") -> 0 | E4: =COUNTIFS('Table 1'!$B$2:$B$163,"Tipo 1*",'Table 1'!$D$2:$D$163,"Strategia",'Table 1'!$E$2:$E$163,"SI") -> 0 | F4: =COUNTIFS('Table 1'!$B$2:$B$163,"Tipo 1*",'Table 1'!$D$2:$D$163,"Relazioni",'Table 1'!$E$2:$E$163,"SI") -> 0 | G4: =COUNTIFS('Table 1'!$B$2:$B$163,"Tipo 1*",'Table 1'!$D$2:$D$163,"Pressione",'Table 1'!$E$2:$E$163,"SI") -> 0 | H4: =COUNTIFS('Table 1'!$B$2:$B$163,"Tipo 1*",'Table 1'!$D$2:$D$163,"Approfondimento",'Table 1'!$E$2:$E$163,"SI") -> 0 | I4: =SUM(C4:H4) -> 0 | J4: =ROUND(I4/18*100,0) -> 0
A5: Tipo 2 | B5: L'Altruista | C5: =COUNTIFS('Table 1'!$B$2:$B$163,"Tipo 2*",'Table 1'!$D$2:$D$163,"Motivazione",'Table 1'!$E$2:$E$163,"SI") -> 0 | D5: =COUNTIFS('Table 1'!$B$2:$B$163,"Tipo 2*",'Table 1'!$D$2:$D$163,"Paura",'Table 1'!$E$2:$E$163,"SI") -> 0 | E5: =COUNTIFS('Table 1'!$B$2:$B$163,"Tipo 2*",'Table 1'!$D$2:$D$163,"Strategia",'Table 1'!$E$2:$E$163,"SI") -> 0 | F5: =COUNTIFS('Table 1'!$B$2:$B$163,"Tipo 2*",'Table 1'!$D$2:$D$163,"Relazioni",'Table 1'!$E$2:$E$163,"SI") -> 0 | G5: =COUNTIFS('Table 1'!$B$2:$B$163,"Tipo 2*",'Table 1'!$D$2:$D$163,"Pressione",'Table 1'!$E$2:$E$163,"SI") -> 0 | H5: =COUNTIFS('Table 1'!$B$2:$B$163,"Tipo 2*",'Table 1'!$D$2:$D$163,"Approfondimento",'Table 1'!$E$2:$E$163,"SI") -> 0 | I5: =SUM(C5:H5) -> 0 | J5: =ROUND(I5/18*100,0) -> 0
A6: Tipo 3 | B6: Il Realizzatore | C6: =COUNTIFS('Table 1'!$B$2:$B$163,"Tipo 3*",'Table 1'!$D$2:$D$163,"Motivazione",'Table 1'!$E$2:$E$163,"SI") -> 0 | D6: =COUNTIFS('Table 1'!$B$2:$B$163,"Tipo 3*",'Table 1'!$D$2:$D$163,"Paura",'Table 1'!$E$2:$E$163,"SI") -> 0 | E6: =COUNTIFS('Table 1'!$B$2:$B$163,"Tipo 3*",'Table 1'!$D$2:$D$163,"Strategia",'Table 1'!$E$2:$E$163,"SI") -> 0 | F6: =COUNTIFS('Table 1'!$B$2:$B$163,"Tipo 3*",'Table 1'!$D$2:$D$163,"Relazioni",'Table 1'!$E$2:$E$163,"SI") -> 0 | G6: =COUNTIFS('Table 1'!$B$2:$B$163,"Tipo 3*",'Table 1'!$D$2:$D$163,"Pressione",'Table 1'!$E$2:$E$163,"SI") -> 0 | H6: =COUNTIFS('Table 1'!$B$2:$B$163,"Tipo 3*",'Table 1'!$D$2:$D$163,"Approfondimento",'Table 1'!$E$2:$E$163,"SI") -> 0 | I6: =SUM(C6:H6) -> 0 | J6: =ROUND(I6/18*100,0) -> 0
A7: Tipo 4 | B7: L'Individualista | C7: =COUNTIFS('Table 1'!$B$2:$B$163,"Tipo 4*",'Table 1'!$D$2:$D$163,"Motivazione",'Table 1'!$E$2:$E$163,"SI") -> 0 | D7: =COUNTIFS('Table 1'!$B$2:$B$163,"Tipo 4*",'Table 1'!$D$2:$D$163,"Paura",'Table 1'!$E$2:$E$163,"SI") -> 0 | E7: =COUNTIFS('Table 1'!$B$2:$B$163,"Tipo 4*",'Table 1'!$D$2:$D$163,"Strategia",'Table 1'!$E$2:$E$163,"SI") -> 0 | F7: =COUNTIFS('Table 1'!$B$2:$B$163,"Tipo 4*",'Table 1'!$D$2:$D$163,"Relazioni",'Table 1'!$E$2:$E$163,"SI") -> 0 | G7: =COUNTIFS('Table 1'!$B$2:$B$163,"Tipo 4*",'Table 1'!$D$2:$D$163,"Pressione",'Table 1'!$E$2:$E$163,"SI") -> 0 | H7: =COUNTIFS('Table 1'!$B$2:$B$163,"Tipo 4*",'Table 1'!$D$2:$D$163,"Approfondimento",'Table 1'!$E$2:$E$163,"SI") -> 0 | I7: =SUM(C7:H7) -> 0 | J7: =ROUND(I7/18*100,0) -> 0
A8: Tipo 5 | B8: L'Osservatore | C8: =COUNTIFS('Table 1'!$B$2:$B$163,"Tipo 5*",'Table 1'!$D$2:$D$163,"Motivazione",'Table 1'!$E$2:$E$163,"SI") -> 0 | D8: =COUNTIFS('Table 1'!$B$2:$B$163,"Tipo 5*",'Table 1'!$D$2:$D$163,"Paura",'Table 1'!$E$2:$E$163,"SI") -> 0 | E8: =COUNTIFS('Table 1'!$B$2:$B$163,"Tipo 5*",'Table 1'!$D$2:$D$163,"Strategia",'Table 1'!$E$2:$E$163,"SI") -> 0 | F8: =COUNTIFS('Table 1'!$B$2:$B$163,"Tipo 5*",'Table 1'!$D$2:$D$163,"Relazioni",'Table 1'!$E$2:$E$163,"SI") -> 0 | G8: =COUNTIFS('Table 1'!$B$2:$B$163,"Tipo 5*",'Table 1'!$D$2:$D$163,"Pressione",'Table 1'!$E$2:$E$163,"SI") -> 0 | H8: =COUNTIFS('Table 1'!$B$2:$B$163,"Tipo 5*",'Table 1'!$D$2:$D$163,"Approfondimento",'Table 1'!$E$2:$E$163,"SI") -> 0 | I8: =SUM(C8:H8) -> 0 | J8: =ROUND(I8/18*100,0) -> 0
A9: Tipo 6 | B9: Il Leale | C9: =COUNTIFS('Table 1'!$B$2:$B$163,"Tipo 6*",'Table 1'!$D$2:$D$163,"Motivazione",'Table 1'!$E$2:$E$163,"SI") -> 0 | D9: =COUNTIFS('Table 1'!$B$2:$B$163,"Tipo 6*",'Table 1'!$D$2:$D$163,"Paura",'Table 1'!$E$2:$E$163,"SI") -> 0 | E9: =COUNTIFS('Table 1'!$B$2:$B$163,"Tipo 6*",'Table 1'!$D$2:$D$163,"Strategia",'Table 1'!$E$2:$E$163,"SI") -> 0 | F9: =COUNTIFS('Table 1'!$B$2:$B$163,"Tipo 6*",'Table 1'!$D$2:$D$163,"Relazioni",'Table 1'!$E$2:$E$163,"SI") -> 0 | G9: =COUNTIFS('Table 1'!$B$2:$B$163,"Tipo 6*",'Table 1'!$D$2:$D$163,"Pressione",'Table 1'!$E$2:$E$163,"SI") -> 0 | H9: =COUNTIFS('Table 1'!$B$2:$B$163,"Tipo 6*",'Table 1'!$D$2:$D$163,"Approfondimento",'Table 1'!$E$2:$E$163,"SI") -> 0 | I9: =SUM(C9:H9) -> 0 | J9: =ROUND(I9/18*100,0) -> 0
A10: Tipo 7 | B10: L'Entusiasta | C10: =COUNTIFS('Table 1'!$B$2:$B$163,"Tipo 7*",'Table 1'!$D$2:$D$163,"Motivazione",'Table 1'!$E$2:$E$163,"SI") -> 0 | D10: =COUNTIFS('Table 1'!$B$2:$B$163,"Tipo 7*",'Table 1'!$D$2:$D$163,"Paura",'Table 1'!$E$2:$E$163,"SI") -> 0 | E10: =COUNTIFS('Table 1'!$B$2:$B$163,"Tipo 7*",'Table 1'!$D$2:$D$163,"Strategia",'Table 1'!$E$2:$E$163,"SI") -> 0 | F10: =COUNTIFS('Table 1'!$B$2:$B$163,"Tipo 7*",'Table 1'!$D$2:$D$163,"Relazioni",'Table 1'!$E$2:$E$163,"SI") -> 0 | G10: =COUNTIFS('Table 1'!$B$2:$B$163,"Tipo 7*",'Table 1'!$D$2:$D$163,"Pressione",'Table 1'!$E$2:$E$163,"SI") -> 0 | H10: =COUNTIFS('Table 1'!$B$2:$B$163,"Tipo 7*",'Table 1'!$D$2:$D$163,"Approfondimento",'Table 1'!$E$2:$E$163,"SI") -> 0 | I10: =SUM(C10:H10) -> 0 | J10: =ROUND(I10/18*100,0) -> 0
A11: Tipo 8 | B11: Il Protettore | C11: =COUNTIFS('Table 1'!$B$2:$B$163,"Tipo 8*",'Table 1'!$D$2:$D$163,"Motivazione",'Table 1'!$E$2:$E$163,"SI") -> 0 | D11: =COUNTIFS('Table 1'!$B$2:$B$163,"Tipo 8*",'Table 1'!$D$2:$D$163,"Paura",'Table 1'!$E$2:$E$163,"SI") -> 0 | E11: =COUNTIFS('Table 1'!$B$2:$B$163,"Tipo 8*",'Table 1'!$D$2:$D$163,"Strategia",'Table 1'!$E$2:$E$163,"SI") -> 0 | F11: =COUNTIFS('Table 1'!$B$2:$B$163,"Tipo 8*",'Table 1'!$D$2:$D$163,"Relazioni",'Table 1'!$E$2:$E$163,"SI") -> 0 | G11: =COUNTIFS('Table 1'!$B$2:$B$163,"Tipo 8*",'Table 1'!$D$2:$D$163,"Pressione",'Table 1'!$E$2:$E$163,"SI") -> 0 | H11: =COUNTIFS('Table 1'!$B$2:$B$163,"Tipo 8*",'Table 1'!$D$2:$D$163,"Approfondimento",'Table 1'!$E$2:$E$163,"SI") -> 0 | I11: =SUM(C11:H11) -> 0 | J11: =ROUND(I11/18*100,0) -> 0
A12: Tipo 9 | B12: Il Pacificatore | C12: =COUNTIFS('Table 1'!$B$2:$B$163,"Tipo 9*",'Table 1'!$D$2:$D$163,"Motivazione",'Table 1'!$E$2:$E$163,"SI") -> 0 | D12: =COUNTIFS('Table 1'!$B$2:$B$163,"Tipo 9*",'Table 1'!$D$2:$D$163,"Paura",'Table 1'!$E$2:$E$163,"SI") -> 0 | E12: =COUNTIFS('Table 1'!$B$2:$B$163,"Tipo 9*",'Table 1'!$D$2:$D$163,"Strategia",'Table 1'!$E$2:$E$163,"SI") -> 0 | F12: =COUNTIFS('Table 1'!$B$2:$B$163,"Tipo 9*",'Table 1'!$D$2:$D$163,"Relazioni",'Table 1'!$E$2:$E$163,"SI") -> 0 | G12: =COUNTIFS('Table 1'!$B$2:$B$163,"Tipo 9*",'Table 1'!$D$2:$D$163,"Pressione",'Table 1'!$E$2:$E$163,"SI") -> 0 | H12: =COUNTIFS('Table 1'!$B$2:$B$163,"Tipo 9*",'Table 1'!$D$2:$D$163,"Approfondimento",'Table 1'!$E$2:$E$163,"SI") -> 0 | I12: =SUM(C12:H12) -> 0 | J12: =ROUND(I12/18*100,0) -> 0
A14: CLASSIFICAZIONE
A15: Tipo principale | B15: =INDEX($A$4:$B$12,MATCH(MAX($I$4:$I$12),$I$4:$I$12,0),2) -> Il Riformatore | D15: Punteggio tipo principale | E15: =MAX($I$4:$I$12) -> 0
A16: Tipo secondario | B16: =INDEX($A$4:$B$12,MATCH(LARGE($I$4:$I$12,2),$I$4:$I$12,0),2) -> Il Riformatore | D16: Punteggio tipo secondario | E16: =LARGE($I$4:$I$12,2) -> 0
A17: Ala sinistra (Tipo N-1) | B17: =INDEX($A$4:$B$12,IF(MATCH(MAX($I$4:$I$12),$I$4:$I$12,0)=1,9,MATCH(MAX($I$4:$I$12),$I$4:$I$12,0)-1),2) -> Il Pacificatore | D17: Punteggio ala sinistra | E17: =INDEX($I$4:$I$12,IF(MATCH(MAX($I$4:$I$12),$I$4:$I$12,0)=1,9,MATCH(MAX($I$4:$I$12),$I$4:$I$12,0)-1)) -> 0
A18: Ala destra (Tipo N+1) | B18: =INDEX($A$4:$B$12,IF(MATCH(MAX($I$4:$I$12),$I$4:$I$12,0)=9,1,MATCH(MAX($I$4:$I$12),$I$4:$I$12,0)+1),2) -> L'Altruista | D18: Punteggio ala destra | E18: =INDEX($I$4:$I$12,IF(MATCH(MAX($I$4:$I$12),$I$4:$I$12,0)=9,1,MATCH(MAX($I$4:$I$12),$I$4:$I$12,0)+1)) -> 0
A19: Le ali sono sempre i due tipi numericamente adiacenti al tipo principale (fissi per teoria); il tipo secondario è invece il tipo con il secondo punteggio più alto, qualunque esso sia — può coincidere con un'ala oppure no.
A21: CONTROLLO COMPILAZIONE
A22: Risposte SI totali | B22: =COUNTIF('Table 1'!$E$2:$E$163,"SI") -> 0
A23: Risposte NO totali | B23: =COUNTIF('Table 1'!$E$2:$E$163,"NO") -> 0
A24: Domande senza risposta | B24: =COUNTBLANK('Table 1'!$E$2:$E$163) -> 162
A26: Il tipo principale è quello con il punteggio totale più alto. Le ali sono i due tipi teoricamente adiacenti al tipo principale; il tipo secondario è il tipo (qualunque esso sia) con il secondo punteggio più alto. La faccetta «Approfondimento» raccoglie tre domande aggiuntive pensate per migliorare la distinzione del tipo e fornire spunti utili alla discussione.

Sheet Interpretazione
B1: INTERPRETAZIONE DEI RISULTATI
B3: Come usare questo foglio
B4: 1) Nel foglio «Punteggi» individua il tipo principale e il secondo tipo. 2) Leggi qui la scheda del tipo principale: desiderio e paura di fondo e indicazioni per discuterne. 3) Nel colloquio, chiedi esempi concreti e verifica soprattutto se le motivazioni e le paure descritte corrispondono all'esperienza della persona. 4) Usa il punteggio di «Approfondimento» come ulteriore elemento di confronto, non come criterio autonomo di classificazione.
B6: TIPO 1 – IL RIFORMATORE
B7: Desiderio fondamentale | C7: essere buono/a, integro/a e coerente; migliorare sé stesso/a e la realtà che lo/la circonda
B8: Paura fondamentale | C8: essere cattivo/a, corrotto/a o moralmente difettoso/a
B9: Punti di approfondimento | C9: Usa le quattro domande di Approfondimento del questionario per verificare con esempi concreti se questi aspetti sono realmente caratteristici della persona, senza considerarli da soli sufficienti a determinare il tipo.
B10: Confronto nel colloquio | C10: Chiedi alla persona quali risposte sente più profondamente proprie, quali invece descrivono solo comportamenti occasionali e soprattutto quale motivazione o paura riconosce dietro quei comportamenti.
B11: Come discuterne | C11: Chiedi esempi concreti recenti e verifica se le motivazioni, le paure e le strategie descritte corrispondono realmente all'esperienza della persona.
B13: TIPO 2 – L'ALTRUISTA
B14: Desiderio fondamentale | C14: sentirsi amato/a ed essere indispensabile per le persone a cui tiene
B15: Paura fondamentale | C15: non essere degno/a di amore se non si rende utile agli altri
B16: Punti di approfondimento | C16: Usa le quattro domande di Approfondimento del questionario per verificare con esempi concreti se questi aspetti sono realmente caratteristici della persona, senza considerarli da soli sufficienti a determinare il tipo.
B17: Confronto nel colloquio | C17: Chiedi alla persona quali risposte sente più profondamente proprie, quali invece descrivono solo comportamenti occasionali e soprattutto quale motivazione o paura riconosce dietro quei comportamenti.
B18: Come discuterne | C18: Chiedi esempi concreti recenti e verifica se le motivazioni, le paure e le strategie descritte corrispondono realmente all'esperienza della persona.
B20: TIPO 3 – IL REALIZZATORE
B21: Desiderio fondamentale | C21: sentirsi di valore attraverso risultati visibili e riconoscimento
B22: Paura fondamentale | C22: non avere alcun valore agli occhi degli altri se non ottiene risultati
B23: Punti di approfondimento | C23: Usa le quattro domande di Approfondimento del questionario per verificare con esempi concreti se questi aspetti sono realmente caratteristici della persona, senza considerarli da soli sufficienti a determinare il tipo.
B24: Confronto nel colloquio | C24: Chiedi alla persona quali risposte sente più profondamente proprie, quali invece descrivono solo comportamenti occasionali e soprattutto quale motivazione o paura riconosce dietro quei comportamenti.
B25: Come discuterne | C25: Chiedi esempi concreti recenti e verifica se le motivazioni, le paure e le strategie descritte corrispondono realmente all'esperienza della persona.
B27: TIPO 4 – L'INDIVIDUALISTA
B28: Desiderio fondamentale | C28: trovare ed esprimere la propria identità autentica e unica
B29: Paura fondamentale | C29: non avere un'identità o un significato personale distinto dagli altri
B30: Punti di approfondimento | C30: Usa le quattro domande di Approfondimento del questionario per verificare con esempi concreti se questi aspetti sono realmente caratteristici della persona, senza considerarli da soli sufficienti a determinare il tipo.
B31: Confronto nel colloquio | C31: Chiedi alla persona quali risposte sente più profondamente proprie, quali invece descrivono solo comportamenti occasionali e soprattutto quale motivazione o paura riconosce dietro quei comportamenti.
B32: Come discuterne | C32: Chiedi esempi concreti recenti e verifica se le motivazioni, le paure e le strategie descritte corrispondono realmente all'esperienza della persona.
B34: TIPO 5 – L'OSSERVATORE
B35: Desiderio fondamentale | C35: sentirsi competente e autosufficiente attraverso la conoscenza
B36: Paura fondamentale | C36: essere sopraffatto/a da richieste per cui non si sente preparato/a
B37: Punti di approfondimento | C37: Usa le quattro domande di Approfondimento del questionario per verificare con esempi concreti se questi aspetti sono realmente caratteristici della persona, senza considerarli da soli sufficienti a determinare il tipo.
B38: Confronto nel colloquio | C38: Chiedi alla persona quali risposte sente più profondamente proprie, quali invece descrivono solo comportamenti occasionali e soprattutto quale motivazione o paura riconosce dietro quei comportamenti.
B39: Come discuterne | C39: Chiedi esempi concreti recenti e verifica se le motivazioni, le paure e le strategie descritte corrispondono realmente all'esperienza della persona.
B41: TIPO 6 – IL LEALE
B42: Desiderio fondamentale | C42: avere sicurezza, guida e punti di riferimento affidabili
B43: Paura fondamentale | C43: restare senza sostegno o protezione di fronte al pericolo
B44: Punti di approfondimento | C44: Usa le quattro domande di Approfondimento del questionario per verificare con esempi concreti se questi aspetti sono realmente caratteristici della persona, senza considerarli da soli sufficienti a determinare il tipo.
B45: Confronto nel colloquio | C45: Chiedi alla persona quali risposte sente più profondamente proprie, quali invece descrivono solo comportamenti occasionali e soprattutto quale motivazione o paura riconosce dietro quei comportamenti.
B46: Come discuterne | C46: Chiedi esempi concreti recenti e verifica se le motivazioni, le paure e le strategie descritte corrispondono realmente all'esperienza della persona.
B48: TIPO 7 – L'ENTUSIASTA
...

Sheet Verifica qualità
A1: Tipo | B1: N. domande | C1: Valutazione complessiva | D1: Ridondanze residue | E1: Osservazione
A2: Tipo 1 – Il Riformatore | B2: 18 | C2: Molto buona | D2: Basse | E2: Buon equilibrio tra principi, autocontrollo, perfezionismo e critica; le domande 16-18 restano utili come approfondimento.
A3: Tipo 2 – L'Altruista | B3: 18 | C3: Molto buona | D3: Basse | E3: Buona distinzione tra cura, bisogno di essere importante, difficoltà a chiedere e bisogno di riconoscimento.
A4: Tipo 3 – Il Realizzatore | B4: 18 | C4: Molto buona | D4: Medio-basse | E4: Forte copertura di risultato, immagine e adattamento; alcune domande restano vicine ma esplorano sfumature diverse.
A5: Tipo 4 – L'Individualista | B5: 18 | C5: Molto buona | D5: Medie | E5: Ricca copertura di autenticità, mancanza, confronto, intensità emotiva e bisogno di essere compreso; qualche area è inevitabilmente vicina.
A6: Tipo 5 – L'Osservatore | B6: 18 | C6: Molto buona | D6: Medie | E6: Buona copertura di competenza, autonomia, privacy e gestione delle risorse; ritirarsi/limitare i contatti rimane un'area con più domande.
A7: Tipo 6 – Il Leale | B7: 18 | C7: Molto buona | D7: Medie | E7: Molto buona distinzione tra prudenza, dubbio, lealtà, autorità e bisogno di conferma; alcune domande su affidabilità sono vicine.
A8: Tipo 7 – L'Entusiasta | B8: 18 | C8: Molto buona | D8: Medie | E8: Ottima copertura di possibilità, evitamento del dolore, stimolazione e difficoltà a rinunciare; alcune domande sulle alternative sono volutamente convergenti.
A9: Tipo 8 – Il Protettore | B9: 18 | C9: Molto buona | D9: Basse | E9: Buona distinzione tra autonomia, confronto, protezione, vulnerabilità e uso della forza.
A10: Tipo 9 – Il Pacificatore | B10: 18 | C10: Molto buona | D10: Medie | E10: Buona copertura di armonia, adattamento, inerzia, conflitto e perdita di priorità personali; alcune domande su mediazione/adattamento sono vicine.
A12: Legenda
A13: Forte | B13: Domanda fortemente pertinente e utile a distinguere il tipo
A14: Buona | B14: Pertinente e utile, ma non necessariamente molto discriminante da sola
A15: Da monitorare | B15: Pertinente ma parzialmente sovrapponibile ad altre domande
A16: Criterio finale | C16: Il questionario è considerato adatto come base esplorativa per una discussione con il compilatore, non come strumento diagnostico o psicometrico validato.
